[2024-04-29T13:06:11.713+0000] {local_task_job_runner.py:120} INFO - ::group::Pre task execution logs
[2024-04-29T13:06:11.741+0000] {taskinstance.py:2073} INFO - Dependencies all met for dep_context=non-requeueable deps ti=<TaskInstance: immo_eliza.training manual__2024-04-29T13:04:31.515074+00:00 [queued]>
[2024-04-29T13:06:11.753+0000] {taskinstance.py:2073} INFO - Dependencies all met for dep_context=requeueable deps ti=<TaskInstance: immo_eliza.training manual__2024-04-29T13:04:31.515074+00:00 [queued]>
[2024-04-29T13:06:11.754+0000] {taskinstance.py:2303} INFO - Starting attempt 1 of 1
[2024-04-29T13:06:11.772+0000] {taskinstance.py:2327} INFO - Executing <Task(PythonOperator): training> on 2024-04-29 13:04:31.515074+00:00
[2024-04-29T13:06:11.782+0000] {warnings.py:110} WARNING - /home/***/.local/lib/python3.12/site-packages/***/task/task_runner/standard_task_runner.py:61: DeprecationWarning: This process (pid=1517) is multi-threaded, use of fork() may lead to deadlocks in the child.
  pid = os.fork()

[2024-04-29T13:06:11.785+0000] {standard_task_runner.py:63} INFO - Started process 1537 to run task
[2024-04-29T13:06:11.784+0000] {standard_task_runner.py:90} INFO - Running: ['***', 'tasks', 'run', 'immo_eliza', 'training', 'manual__2024-04-29T13:04:31.515074+00:00', '--job-id', '20', '--raw', '--subdir', 'DAGS_FOLDER/eliza.py', '--cfg-path', '/tmp/tmpbhgmbwc6']
[2024-04-29T13:06:11.787+0000] {standard_task_runner.py:91} INFO - Job 20: Subtask training
[2024-04-29T13:06:11.845+0000] {task_command.py:426} INFO - Running <TaskInstance: immo_eliza.training manual__2024-04-29T13:04:31.515074+00:00 [running]> on host 2f572e0ad8bc
[2024-04-29T13:06:11.961+0000] {taskinstance.py:2644} INFO - Exporting env vars: AIRFLOW_CTX_DAG_OWNER='***' AIRFLOW_CTX_DAG_ID='immo_eliza' AIRFLOW_CTX_TASK_ID='training' AIRFLOW_CTX_EXECUTION_DATE='2024-04-29T13:04:31.515074+00:00' AIRFLOW_CTX_TRY_NUMBER='1' AIRFLOW_CTX_DAG_RUN_ID='manual__2024-04-29T13:04:31.515074+00:00'
[2024-04-29T13:06:11.963+0000] {taskinstance.py:430} INFO - ::endgroup::
[2024-04-29T13:06:11.988+0000] {taskinstance.py:441} INFO - ::group::Post task execution logs
[2024-04-29T13:06:11.989+0000] {taskinstance.py:2890} ERROR - Task failed with exception
Traceback (most recent call last):
  File "/home/airflow/.local/lib/python3.12/site-packages/airflow/models/taskinstance.py", line 465, in _execute_task
    result = _execute_callable(context=context, **execute_callable_kwargs)
             ^^^^^^^^^^^^^^^^^^^^^^^^^^^^^^^^^^^^^^^^^^^^^^^^^^^^^^^^^^^^^
  File "/home/airflow/.local/lib/python3.12/site-packages/airflow/models/taskinstance.py", line 432, in _execute_callable
    return execute_callable(context=context, **execute_callable_kwargs)
           ^^^^^^^^^^^^^^^^^^^^^^^^^^^^^^^^^^^^^^^^^^^^^^^^^^^^^^^^^^^^
  File "/home/airflow/.local/lib/python3.12/site-packages/airflow/models/baseoperator.py", line 400, in wrapper
    return func(self, *args, **kwargs)
           ^^^^^^^^^^^^^^^^^^^^^^^^^^^
  File "/home/airflow/.local/lib/python3.12/site-packages/airflow/operators/python.py", line 235, in execute
    return_value = self.execute_callable()
                   ^^^^^^^^^^^^^^^^^^^^^^^
  File "/home/airflow/.local/lib/python3.12/site-packages/airflow/operators/python.py", line 252, in execute_callable
    return self.python_callable(*self.op_args, **self.op_kwargs)
           ^^^^^^^^^^^^^^^^^^^^^^^^^^^^^^^^^^^^^^^^^^^^^^^^^^^^^
  File "/opt/airflow/dags/eliza/machinelearning/train.py", line 14, in train
    data = pd.read_csv("data/cleaned/data.csv")
           ^^^^^^^^^^^^^^^^^^^^^^^^^^^^^^^^^^^^
  File "/home/airflow/.local/lib/python3.12/site-packages/pandas/io/parsers/readers.py", line 948, in read_csv
    return _read(filepath_or_buffer, kwds)
           ^^^^^^^^^^^^^^^^^^^^^^^^^^^^^^^
  File "/home/airflow/.local/lib/python3.12/site-packages/pandas/io/parsers/readers.py", line 611, in _read
    parser = TextFileReader(filepath_or_buffer, **kwds)
             ^^^^^^^^^^^^^^^^^^^^^^^^^^^^^^^^^^^^^^^^^^
  File "/home/airflow/.local/lib/python3.12/site-packages/pandas/io/parsers/readers.py", line 1448, in __init__
    self._engine = self._make_engine(f, self.engine)
                   ^^^^^^^^^^^^^^^^^^^^^^^^^^^^^^^^^
  File "/home/airflow/.local/lib/python3.12/site-packages/pandas/io/parsers/readers.py", line 1705, in _make_engine
    self.handles = get_handle(
                   ^^^^^^^^^^^
  File "/home/airflow/.local/lib/python3.12/site-packages/pandas/io/common.py", line 863, in get_handle
    handle = open(
             ^^^^^
FileNotFoundError: [Errno 2] No such file or directory: 'data/cleaned/data.csv'
[2024-04-29T13:06:12.010+0000] {taskinstance.py:1205} INFO - Marking task as FAILED. dag_id=immo_eliza, task_id=training, execution_date=20240429T130431, start_date=20240429T130611, end_date=20240429T130612
[2024-04-29T13:06:12.025+0000] {standard_task_runner.py:110} ERROR - Failed to execute job 20 for task training ([Errno 2] No such file or directory: 'data/cleaned/data.csv'; 1537)
[2024-04-29T13:06:12.040+0000] {local_task_job_runner.py:240} INFO - Task exited with return code 1
[2024-04-29T13:06:12.061+0000] {taskinstance.py:3482} INFO - 0 downstream tasks scheduled from follow-on schedule check
[2024-04-29T13:06:12.063+0000] {local_task_job_runner.py:222} INFO - ::endgroup::
